
<!--<?xml version="1.0"?>-->

<robot name="cabinet_0007_robot" >

    <link name="world" />


<!-- cabinet_0007 -->

    <!-- cabinet_0007 -->
    <link name="cabinet_0007">
        <inertial>
            <origin xyz="0 0 0" />
            <mass value="78.1464098482814" />
            <inertia ixx="0.0" ixy="0.0" ixz="0.0" iyy="0.0" iyz="0.0" izz="0.0" />
        </inertial>
        <visual>
            <origin xyz="0 0 0" />
            <geometry>
                <mesh filename="none_motion.processed.obj" rpy="0 0 0" />
            </geometry>
        </visual>
        <collision>
            <origin xyz="0 0 0" />
            <geometry>
                <mesh filename="none_motion_vhacd.obj" rpy="0 0 0" />
            </geometry>
        </collision>
    </link>


    <joint name="joint_structure" type="fixed">
        <origin xyz="0.000 0.000 0.000" rpy="0 0 0" />
        <parent link="world" />
        <child link="cabinet_0007" />
    </joint>

    
    <link name="dof_rootd_Aa002_t">
        <inertial>
            <origin xyz="-0.0289855 -0.195652 -0.40942" />
            <mass value="14.528817930507028" />
            <inertia ixx="0.0" ixy="0.0" ixz="0.0" iyy="0.0" iyz="0.0" izz="0.0" />
        </inertial>
        <visual>
            <origin xyz="-0.0289855 -0.195652 -0.40942" />
            <geometry>
                <mesh filename="dof_rootd_Aa002_t.processed.obj" rpy="0 0 0" />
            </geometry>
        </visual>
        <collision>
            <origin xyz="-0.0289855 -0.195652 -0.40942" />
            <geometry>
                <mesh filename="dof_rootd_Aa002_t_vhacd.obj" rpy="0 0 0" />
            </geometry>
        </collision>
    </link>

    <joint name="dof_rootd_Aa002_t" type="prismatic">
        <origin xyz="0.0289855 0.195652 0.40942" rpy="0 0 0" />
        <parent link="cabinet_0007" />
        <child link="dof_rootd_Aa002_t" />
        <axis xyz="1.0 0.0 2.22045e-16" />
        <dynamics friction="0" />
        <limit lower="0.0" upper="0.4874083048275276"/>
    </joint>
    
        
    
    <link name="dof_rootd_Aa003_t">
        <inertial>
            <origin xyz="-0.0289855 3.41916e-17 -0.205918" />
            <mass value="12.787111738626614" />
            <inertia ixx="0.0" ixy="0.0" ixz="0.0" iyy="0.0" iyz="0.0" izz="0.0" />
        </inertial>
        <visual>
            <origin xyz="-0.0289855 3.41916e-17 -0.205918" />
            <geometry>
                <mesh filename="dof_rootd_Aa003_t.processed.obj" rpy="0 0 0" />
            </geometry>
        </visual>
        <collision>
            <origin xyz="-0.0289855 3.41916e-17 -0.205918" />
            <geometry>
                <mesh filename="dof_rootd_Aa003_t_vhacd.obj" rpy="0 0 0" />
            </geometry>
        </collision>
    </link>

    <joint name="dof_rootd_Aa003_t" type="prismatic">
        <origin xyz="0.0289855 -3.41916e-17 0.205918" rpy="0 0 0" />
        <parent link="cabinet_0007" />
        <child link="dof_rootd_Aa003_t" />
        <axis xyz="1.0 -3.46945e-18 1.11022e-16" />
        <dynamics friction="0" />
        <limit lower="0.0" upper="0.26297229132770267"/>
    </joint>
    
        
    
    <link name="dof_rootd_Aa004_t">
        <inertial>
            <origin xyz="-0.0289855 3.41916e-17 0.030797" />
            <mass value="6.46347403199372" />
            <inertia ixx="0.0" ixy="0.0" ixz="0.0" iyy="0.0" iyz="0.0" izz="0.0" />
        </inertial>
        <visual>
            <origin xyz="-0.0289855 3.41916e-17 0.030797" />
            <geometry>
                <mesh filename="dof_rootd_Aa004_t.processed.obj" rpy="0 0 0" />
            </geometry>
        </visual>
        <collision>
            <origin xyz="-0.0289855 3.41916e-17 0.030797" />
            <geometry>
                <mesh filename="dof_rootd_Aa004_t_vhacd.obj" rpy="0 0 0" />
            </geometry>
        </collision>
    </link>

    <joint name="dof_rootd_Aa004_t" type="prismatic">
        <origin xyz="0.0289855 -3.41916e-17 -0.030797" rpy="0 0 0" />
        <parent link="cabinet_0007" />
        <child link="dof_rootd_Aa004_t" />
        <axis xyz="1.0 -3.46945e-18 1.17961e-16" />
        <dynamics friction="0" />
        <limit lower="0.0" upper="0.38359051987409504"/>
    </joint>
    
        
    
    <link name="dof_rootd_Aa005_t">
        <inertial>
            <origin xyz="-0.0289855 6.43608e-18 0.267512" />
            <mass value="6.503726603764189" />
            <inertia ixx="0.0" ixy="0.0" ixz="0.0" iyy="0.0" iyz="0.0" izz="0.0" />
        </inertial>
        <visual>
            <origin xyz="-0.0289855 6.43608e-18 0.267512" />
            <geometry>
                <mesh filename="dof_rootd_Aa005_t.processed.obj" rpy="0 0 0" />
            </geometry>
        </visual>
        <collision>
            <origin xyz="-0.0289855 6.43608e-18 0.267512" />
            <geometry>
                <mesh filename="dof_rootd_Aa005_t_vhacd.obj" rpy="0 0 0" />
            </geometry>
        </collision>
    </link>

    <joint name="dof_rootd_Aa005_t" type="prismatic">
        <origin xyz="0.0289855 -6.43608e-18 -0.267512" rpy="0 0 0" />
        <parent link="cabinet_0007" />
        <child link="dof_rootd_Aa005_t" />
        <axis xyz="1.0 2.77556e-17 1.11022e-16" />
        <dynamics friction="0.0" />
        <limit lower="0.0" upper="0.3765409611138598"/>
    </joint>
    
        
    
    <link name="dof_rootd_Aa001_t">
        <inertial>
            <origin xyz="-0.0289855 0.195652 -0.40942" />
            <mass value="6.168071125263637" />
            <inertia ixx="0.0" ixy="0.0" ixz="0.0" iyy="0.0" iyz="0.0" izz="0.0" />
        </inertial>
        <visual>
            <origin xyz="-0.0289855 0.195652 -0.40942" />
            <geometry>
                <mesh filename="dof_rootd_Aa001_t.processed.obj" rpy="0 0 0" />
            </geometry>
        </visual>
        <collision>
            <origin xyz="-0.0289855 0.195652 -0.40942" />
            <geometry>
                <mesh filename="dof_rootd_Aa001_t_vhacd.obj" rpy="0 0 0" />
            </geometry>
        </collision>
    </link>

    <joint name="dof_rootd_Aa001_t" type="prismatic">
        <origin xyz="0.0289855 -0.195652 0.40942" rpy="0 0 0" />
        <parent link="cabinet_0007" />
        <child link="dof_rootd_Aa001_t" />
        <axis xyz="1.0 0.0 1.66533e-16" />
        <dynamics friction="0" />
        <limit lower="0.0" upper="0.2810831471476685"/>
    </joint>
    
        

</robot>
        